<?xml version="1.0" encoding="utf-8"?>
<!-- This URDF was automatically created by SolidWorks to URDF Exporter! Originally created by Stephen Brawner (brawner@gmail.com) 
     Commit Version: 1.6.0-4-g7f85cfe  Build Version: 1.6.7995.38578
     For more information, please see http://wiki.ros.org/sw_urdf_exporter -->
<robot
  name="HotDog">
  <link
    name="BODY_LINK">
    <inertial>
      <origin
        xyz="-0.0371687442236052 0.00016322891231972 -5.50209374861353E-05"
        rpy="0 0 0" />
      <mass
        value="1.06660031766174" />
      <inertia
        ixx="0.00119304411179781"
        ixy="-1.49726624538115E-10"
        ixz="4.37319154600914E-06"
        iyy="0.0054466046795462"
        iyz="-6.71769991102411E-08"
        izz="0.00569315083713373" />
    </inertial>
    <visual>
      <origin
        xyz="0 0 0"
        rpy="0 0 0" />
      <geometry>
        <mesh
          filename="package://HotDog/meshes/BODY_LINK.STL" />
      </geometry>
      <material
        name="">
        <color
          rgba="0.752941176470588 0.752941176470588 0.752941176470588 1" />
      </material>
    </visual>
    <collision>
      <origin
        xyz="0 0 0"
        rpy="0 0 0" />
      <geometry>
        <mesh
          filename="package://HotDog/meshes/BODY_LINK.STL" />
      </geometry>
    </collision>
  </link>
  <link
    name="LF_JIAN_LINK">
    <inertial>
      <origin
        xyz="-0.000741533210672114 -4.7995835830289E-06 -0.028405263004785"
        rpy="0 0 0" />
      <mass
        value="0.164648707873323" />
      <inertia
        ixx="0.000363210273359673"
        ixy="-1.83547355492689E-08"
        ixz="-1.46953561317183E-07"
        iyy="0.0003706849708134"
        iyz="6.33178541948565E-09"
        izz="0.000108616132557141" />
    </inertial>
    <visual>
      <origin
        xyz="0 0 0"
        rpy="0 0 0" />
      <geometry>
        <mesh
          filename="package://HotDog/meshes/LF_JIAN_LINK.STL" />
      </geometry>
      <material
        name="">
        <color
          rgba="0.752941176470588 0.752941176470588 0.752941176470588 1" />
      </material>
    </visual>
    <collision>
      <origin
        xyz="0 0 0"
        rpy="0 0 0" />
      <geometry>
        <mesh
          filename="package://HotDog/meshes/LF_JIAN_LINK.STL" />
      </geometry>
    </collision>
  </link>
  <joint
    name="LF_JIAN_JOINT"
    type="revolute">
    <origin
      xyz="0.1199 0.04805 -0.001"
      rpy="1.5708 0 1.5708" />
    <parent
      link="BODY_LINK" />
    <child
      link="LF_JIAN_LINK" />
    <axis
      xyz="0 0 1" />
    <limit
      lower="-1.5708"
      upper="1.5708"
      effort="0"
      velocity="0" />
  </joint>
  <link
    name="LF_THIGH_LINK">
    <inertial>
      <origin
        xyz="0.0508525846899987 -0.00075850600525168 -5.73760741986035E-05"
        rpy="0 0 0" />
      <mass
        value="0.0986910738752765" />
      <inertia
        ixx="1.83065940672543E-05"
        ixy="2.05585256451938E-06"
        ixz="-3.32207876151063E-07"
        iyy="0.000188717504633026"
        iyz="-7.59277950745174E-08"
        izz="0.000205571153181477" />
    </inertial>
    <visual>
      <origin
        xyz="0 0 0"
        rpy="0 0 0" />
      <geometry>
        <mesh
          filename="package://HotDog/meshes/LF_THIGH_LINK.STL" />
      </geometry>
      <material
        name="">
        <color
          rgba="0.752941176470588 0.752941176470588 0.752941176470588 1" />
      </material>
    </visual>
    <collision>
      <origin
        xyz="0 0 0"
        rpy="0 0 0" />
      <geometry>
        <mesh
          filename="package://HotDog/meshes/LF_THIGH_LINK.STL" />
      </geometry>
    </collision>
  </link>
  <joint
    name="LF_THIGH_JOINT"
    type="revolute">
    <origin
      xyz="0.05305 0 0"
      rpy="-1.5708 0.023282 -1.5708" />
    <parent
      link="LF_JIAN_LINK" />
    <child
      link="LF_THIGH_LINK" />
    <axis
      xyz="0 0 -1" />
    <limit
      lower="-1.5708"
      upper="1.5708"
      effort="0"
      velocity="0" />
  </joint>
  <link
    name="LF_SHANK_LINK">
    <inertial>
      <origin
        xyz="0.0524852485214341 -0.0020157518410453 4.12966244767166E-06"
        rpy="0 0 0" />
      <mass
        value="0.0485389866008694" />
      <inertia
        ixx="7.1966174171715E-06"
        ixy="9.47458566096196E-07"
        ixz="1.93275477884366E-08"
        iyy="9.53297494158792E-05"
        iyz="8.07462630093549E-10"
        izz="9.98870067459658E-05" />
    </inertial>
    <visual>
      <origin
        xyz="0 0 0"
        rpy="0 0 0" />
      <geometry>
        <mesh
          filename="package://HotDog/meshes/LF_SHANK_LINK.STL" />
      </geometry>
      <material
        name="">
        <color
          rgba="0.752941176470588 0.752941176470588 0.752941176470588 1" />
      </material>
    </visual>
    <collision>
      <origin
        xyz="0 0 0"
        rpy="0 0 0" />
      <geometry>
        <mesh
          filename="package://HotDog/meshes/LF_SHANK_LINK.STL" />
      </geometry>
    </collision>
  </link>
  <joint
    name="LF_SHANK_JOINT"
    type="revolute">
    <origin
      xyz="0.13499 -0.0012933 0"
      rpy="0 0 -1.5941" />
    <parent
      link="LF_THIGH_LINK" />
    <child
      link="LF_SHANK_LINK" />
    <axis
      xyz="0 0 -1" />
    <limit
      lower="-1.5708"
      upper="1.5708"
      effort="0"
      velocity="0" />
  </joint>
  <link
    name="LF_R_LINK">
    <inertial>
      <origin
        xyz="-2.77555756156289E-17 0 0"
        rpy="0 0 0" />
      <mass
        value="6.54498469497874E-05" />
      <inertia
        ixx="1.63624617374468E-10"
        ixy="-6.76961594559568E-48"
        ixz="0"
        iyy="1.63624617374468E-10"
        iyz="5.68481213279604E-37"
        izz="1.63624617374468E-10" />
    </inertial>
    <visual>
      <origin
        xyz="0 0 0"
        rpy="0 0 0" />
      <geometry>
        <mesh
          filename="package://HotDog/meshes/LF_R_LINK.STL" />
      </geometry>
      <material
        name="">
        <color
          rgba="0.792156862745098 0.819607843137255 0.933333333333333 1" />
      </material>
    </visual>
    <collision>
      <origin
        xyz="0 0 0"
        rpy="0 0 0" />
      <geometry>
        <mesh
          filename="package://HotDog/meshes/LF_R_LINK.STL" />
      </geometry>
    </collision>
  </link>
  <joint
    name="LF_R_JOINT"
    type="revolute">
    <origin
      xyz="0.122 0 0"
      rpy="1.5708 0 0" />
    <parent
      link="LF_SHANK_LINK" />
    <child
      link="LF_R_LINK" />
    <axis
      xyz="0 0 -1" />
    <limit
      lower="-1.5708"
      upper="1.5708"
      effort="0"
      velocity="0" />
  </joint>
  <link
    name="LF_P_LINK">
    <inertial>
      <origin
        xyz="0 0 -2.77555756156289E-17"
        rpy="0 0 0" />
      <mass
        value="6.54498469497874E-05" />
      <inertia
        ixx="1.63624617374468E-10"
        ixy="0"
        ixz="0"
        iyy="1.63624617374468E-10"
        iyz="0"
        izz="1.63624617374468E-10" />
    </inertial>
    <visual>
      <origin
        xyz="0 0 0"
        rpy="0 0 0" />
      <geometry>
        <mesh
          filename="package://HotDog/meshes/LF_P_LINK.STL" />
      </geometry>
      <material
        name="">
        <color
          rgba="0.792156862745098 0.819607843137255 0.933333333333333 1" />
      </material>
    </visual>
    <collision>
      <origin
        xyz="0 0 0"
        rpy="0 0 0" />
      <geometry>
        <mesh
          filename="package://HotDog/meshes/LF_P_LINK.STL" />
      </geometry>
    </collision>
  </link>
  <joint
    name="LF_P_JOINT"
    type="revolute">
    <origin
      xyz="0 0 0"
      rpy="0 1.5708 0" />
    <parent
      link="LF_R_LINK" />
    <child
      link="LF_P_LINK" />
    <axis
      xyz="0 0 -1" />
    <limit
      lower="-1.5708"
      upper="1.5708"
      effort="0"
      velocity="0" />
  </joint>
  <link
    name="LF_Y_LINK">
    <inertial>
      <origin
        xyz="0 -2.77555756156289E-17 0"
        rpy="0 0 0" />
      <mass
        value="6.54498469497874E-05" />
      <inertia
        ixx="1.63624617374468E-10"
        ixy="0"
        ixz="0"
        iyy="1.63624617374468E-10"
        iyz="0"
        izz="1.63624617374468E-10" />
    </inertial>
    <visual>
      <origin
        xyz="0 0 0"
        rpy="0 0 0" />
      <geometry>
        <mesh
          filename="package://HotDog/meshes/LF_Y_LINK.STL" />
      </geometry>
      <material
        name="">
        <color
          rgba="0.792156862745098 0.819607843137255 0.933333333333333 1" />
      </material>
    </visual>
    <collision>
      <origin
        xyz="0 0 0"
        rpy="0 0 0" />
      <geometry>
        <mesh
          filename="package://HotDog/meshes/LF_Y_LINK.STL" />
      </geometry>
    </collision>
  </link>
  <joint
    name="LF_Y_JOINT"
    type="revolute">
    <origin
      xyz="0 0 0"
      rpy="1.5708 0 0" />
    <parent
      link="LF_P_LINK" />
    <child
      link="LF_Y_LINK" />
    <axis
      xyz="0 0 1" />
    <limit
      lower="-1.5708"
      upper="1.5708"
      effort="0"
      velocity="0" />
  </joint>
  <link
    name="LB_JIAN_LINK">
    <inertial>
      <origin
        xyz="0.00111242445505096 6.9888123392964E-05 -0.0282503390893783"
        rpy="0 0 0" />
      <mass
        value="0.326912693320869" />
      <inertia
        ixx="0.000431834496212363"
        ixy="2.03421652435572E-08"
        ixz="-1.91870500374397E-07"
        iyy="0.000412383474998457"
        iyz="-4.11327652877867E-09"
        izz="0.000148210210042104" />
    </inertial>
    <visual>
      <origin
        xyz="0 0 0"
        rpy="0 0 0" />
      <geometry>
        <mesh
          filename="package://HotDog/meshes/LB_JIAN_LINK.STL" />
      </geometry>
      <material
        name="">
        <color
          rgba="0.752941176470588 0.752941176470588 0.752941176470588 1" />
      </material>
    </visual>
    <collision>
      <origin
        xyz="0 0 0"
        rpy="0 0 0" />
      <geometry>
        <mesh
          filename="package://HotDog/meshes/LB_JIAN_LINK.STL" />
      </geometry>
    </collision>
  </link>
  <joint
    name="LB_JIAN_JOINT"
    type="revolute">
    <origin
      xyz="-0.1219 0.04805 -0.001"
      rpy="-1.5708 0 1.5708" />
    <parent
      link="BODY_LINK" />
    <child
      link="LB_JIAN_LINK" />
    <axis
      xyz="0 0 -1" />
    <limit
      lower="-1.5708"
      upper="1.5708"
      effort="0"
      velocity="0" />
  </joint>
  <link
    name="LB_THIGH_LINK">
    <inertial>
      <origin
        xyz="0.0434722231723628 -0.000195922727933742 -0.00150945945314165"
        rpy="0 0 0" />
      <mass
        value="0.126723876610191" />
      <inertia
        ixx="2.26464638283808E-05"
        ixy="8.7166109356304E-08"
        ixz="-3.30711530704509E-07"
        iyy="0.00021296049921749"
        iyz="-8.3920203329765E-08"
        izz="0.000231538395396995" />
    </inertial>
    <visual>
      <origin
        xyz="0 0 0"
        rpy="0 0 0" />
      <geometry>
        <mesh
          filename="package://HotDog/meshes/LB_THIGH_LINK.STL" />
      </geometry>
      <material
        name="">
        <color
          rgba="0.752941176470588 0.752941176470588 0.752941176470588 1" />
      </material>
    </visual>
    <collision>
      <origin
        xyz="0 0 0"
        rpy="0 0 0" />
      <geometry>
        <mesh
          filename="package://HotDog/meshes/LB_THIGH_LINK.STL" />
      </geometry>
    </collision>
  </link>
  <joint
    name="LB_THIGH_JOINT"
    type="revolute">
    <origin
      xyz="0.05305 -0.0022197 -0.0034125"
      rpy="1.5708 -0.013702 1.5708" />
    <parent
      link="LB_JIAN_LINK" />
    <child
      link="LB_THIGH_LINK" />
    <axis
      xyz="0 0 1" />
    <limit
      lower="-1.5708"
      upper="1.5708"
      effort="0"
      velocity="0" />
  </joint>
  <link
    name="LB_SHANK_LINK">
    <inertial>
      <origin
        xyz="0.052523902247848 -7.14126603541809E-05 4.13478116592647E-06"
        rpy="0 0 0" />
      <mass
        value="0.0485390257312316" />
      <inertia
        ixx="7.24730043817087E-06"
        ixy="-2.31551978302083E-06"
        ixz="1.92851628424292E-08"
        iyy="9.52790783422838E-05"
        iyz="1.52397597956579E-09"
        izz="9.98870153478349E-05" />
    </inertial>
    <visual>
      <origin
        xyz="0 0 0"
        rpy="0 0 0" />
      <geometry>
        <mesh
          filename="package://HotDog/meshes/LB_SHANK_LINK.STL" />
      </geometry>
      <material
        name="">
        <color
          rgba="0.752941176470588 0.752941176470588 0.752941176470588 1" />
      </material>
    </visual>
    <collision>
      <origin
        xyz="0 0 0"
        rpy="0 0 0" />
      <geometry>
        <mesh
          filename="package://HotDog/meshes/LB_SHANK_LINK.STL" />
      </geometry>
    </collision>
  </link>
  <joint
    name="LB_SHANK_JOINT"
    type="revolute">
    <origin
      xyz="0.135 0 0"
      rpy="0 0 -1.6215" />
    <parent
      link="LB_THIGH_LINK" />
    <child
      link="LB_SHANK_LINK" />
    <axis
      xyz="0 0 -1" />
    <limit
      lower="-1.5708"
      upper="1.5708"
      effort="0"
      velocity="0" />
  </joint>
  <link
    name="LB_R_LINK">
    <inertial>
      <origin
        xyz="-1.73472347597681E-18 0 0"
        rpy="0 0 0" />
      <mass
        value="6.54498469497874E-05" />
      <inertia
        ixx="1.63624617374468E-10"
        ixy="-1.62941245724989E-43"
        ixz="0"
        iyy="1.63624617374468E-10"
        iyz="0"
        izz="1.63624617374468E-10" />
    </inertial>
    <visual>
      <origin
        xyz="0 0 0"
        rpy="0 0 0" />
      <geometry>
        <mesh
          filename="package://HotDog/meshes/LB_R_LINK.STL" />
      </geometry>
      <material
        name="">
        <color
          rgba="0.792156862745098 0.819607843137255 0.933333333333333 1" />
      </material>
    </visual>
    <collision>
      <origin
        xyz="0 0 0"
        rpy="0 0 0" />
      <geometry>
        <mesh
          filename="package://HotDog/meshes/LB_R_LINK.STL" />
      </geometry>
    </collision>
  </link>
  <joint
    name="LB_R_JOINT"
    type="revolute">
    <origin
      xyz="0.12192 0.0045163 0"
      rpy="1.5708 0 0.037028" />
    <parent
      link="LB_SHANK_LINK" />
    <child
      link="LB_R_LINK" />
    <axis
      xyz="0 0 -1" />
    <limit
      lower="-1.5708"
      upper="1.5708"
      effort="0"
      velocity="0" />
  </joint>
  <link
    name="LB_P_LINK">
    <inertial>
      <origin
        xyz="0 0 -1.73472347597681E-18"
        rpy="0 0 0" />
      <mass
        value="6.54498469497874E-05" />
      <inertia
        ixx="1.63624617374468E-10"
        ixy="0"
        ixz="0"
        iyy="1.63624617374468E-10"
        iyz="-1.62941245724989E-43"
        izz="1.63624617374468E-10" />
    </inertial>
    <visual>
      <origin
        xyz="0 0 0"
        rpy="0 0 0" />
      <geometry>
        <mesh
          filename="package://HotDog/meshes/LB_P_LINK.STL" />
      </geometry>
      <material
        name="">
        <color
          rgba="0.792156862745098 0.819607843137255 0.933333333333333 1" />
      </material>
    </visual>
    <collision>
      <origin
        xyz="0 0 0"
        rpy="0 0 0" />
      <geometry>
        <mesh
          filename="package://HotDog/meshes/LB_P_LINK.STL" />
      </geometry>
    </collision>
  </link>
  <joint
    name="LB_P_JOINT"
    type="revolute">
    <origin
      xyz="0 0 0"
      rpy="0 1.5708 0" />
    <parent
      link="LB_R_LINK" />
    <child
      link="LB_P_LINK" />
    <axis
      xyz="0 0 -1" />
    <limit
      lower="-1.5708"
      upper="1.5708"
      effort="0"
      velocity="0" />
  </joint>
  <link
    name="LB_Y_LINK">
    <inertial>
      <origin
        xyz="0 -1.73472347597681E-18 0"
        rpy="0 0 0" />
      <mass
        value="6.54498469497874E-05" />
      <inertia
        ixx="1.63624617374468E-10"
        ixy="0"
        ixz="0"
        iyy="1.63624617374468E-10"
        iyz="1.62941245724989E-43"
        izz="1.63624617374468E-10" />
    </inertial>
    <visual>
      <origin
        xyz="0 0 0"
        rpy="0 0 0" />
      <geometry>
        <mesh
          filename="package://HotDog/meshes/LB_Y_LINK.STL" />
      </geometry>
      <material
        name="">
        <color
          rgba="0.792156862745098 0.819607843137255 0.933333333333333 1" />
      </material>
    </visual>
    <collision>
      <origin
        xyz="0 0 0"
        rpy="0 0 0" />
      <geometry>
        <mesh
          filename="package://HotDog/meshes/LB_Y_LINK.STL" />
      </geometry>
    </collision>
  </link>
  <joint
    name="LB_Y_JOINT"
    type="revolute">
    <origin
      xyz="0 0 0"
      rpy="1.5708 0 0" />
    <parent
      link="LB_P_LINK" />
    <child
      link="LB_Y_LINK" />
    <axis
      xyz="0 0 1" />
    <limit
      lower="-1.5708"
      upper="1.5708"
      effort="0"
      velocity="0" />
  </joint>
  <link
    name="RF_JIAN_LINK">
    <inertial>
      <origin
        xyz="-0.000741503529284405 9.43071581690798E-06 -0.0276445307185166"
        rpy="0 0 0" />
      <mass
        value="0.164648707873323" />
      <inertia
        ixx="0.000363212926897092"
        ixy="1.42267921416376E-07"
        ixz="1.96247015673297E-07"
        iyy="0.000370682317275983"
        iyz="2.06308227531926E-09"
        izz="0.00010861613255714" />
    </inertial>
    <visual>
      <origin
        xyz="0 0 0"
        rpy="0 0 0" />
      <geometry>
        <mesh
          filename="package://HotDog/meshes/RF_JIAN_LINK.STL" />
      </geometry>
      <material
        name="">
        <color
          rgba="0.752941176470588 0.752941176470588 0.752941176470588 1" />
      </material>
    </visual>
    <collision>
      <origin
        xyz="0 0 0"
        rpy="0 0 0" />
      <geometry>
        <mesh
          filename="package://HotDog/meshes/RF_JIAN_LINK.STL" />
      </geometry>
    </collision>
  </link>
  <joint
    name="RF_JIAN_JOINT"
    type="revolute">
    <origin
      xyz="0.1199 -0.04795 -0.001"
      rpy="-1.5708 0.021756 -1.5708" />
    <parent
      link="BODY_LINK" />
    <child
      link="RF_JIAN_LINK" />
    <axis
      xyz="0 0 1" />
    <limit
      lower="-1.5708"
      upper="1.5708"
      effort="0"
      velocity="0" />
  </joint>
  <link
    name="RF_THIGH_LINK">
    <inertial>
      <origin
        xyz="0.0512196578451125 0.00078015605506318 0.000191818707834981"
        rpy="0 0 0" />
      <mass
        value="0.0976231637562044" />
      <inertia
        ixx="1.83918020054249E-05"
        ixy="-2.51221162802734E-06"
        ixz="3.32557226527169E-07"
        iyy="0.000188568607420342"
        iyz="-7.43826735038509E-08"
        izz="0.000205508953934319" />
    </inertial>
    <visual>
      <origin
        xyz="0 0 0"
        rpy="0 0 0" />
      <geometry>
        <mesh
          filename="package://HotDog/meshes/RF_THIGH_LINK.STL" />
      </geometry>
      <material
        name="">
        <color
          rgba="0.752941176470588 0.752941176470588 0.752941176470588 1" />
      </material>
    </visual>
    <collision>
      <origin
        xyz="0 0 0"
        rpy="0 0 0" />
      <geometry>
        <mesh
          filename="package://HotDog/meshes/RF_THIGH_LINK.STL" />
      </geometry>
    </collision>
  </link>
  <joint
    name="RF_THIGH_JOINT"
    type="revolute">
    <origin
      xyz="0.053037 -0.001 0"
      rpy="-1.5708 -0.00052673 1.549" />
    <parent
      link="RF_JIAN_LINK" />
    <child
      link="RF_THIGH_LINK" />
    <axis
      xyz="0.021754 0 -0.99976" />
    <limit
      lower="-1.5708"
      upper="1.5708"
      effort="0"
      velocity="0" />
  </joint>
  <link
    name="RF_SHANK_LINK">
    <inertial>
      <origin
        xyz="0.0524852553396524 -0.00201575621178718 4.13470284280071E-06"
        rpy="0 0 0" />
      <mass
        value="0.0485390235838856" />
      <inertia
        ixx="7.19662087968634E-06"
        ixy="9.47458060345142E-07"
        ixz="1.93286341128723E-08"
        iyy="9.53297551675703E-05"
        iyz="8.08952802420755E-10"
        izz="9.98870127222629E-05" />
    </inertial>
    <visual>
      <origin
        xyz="0 0 0"
        rpy="0 0 0" />
      <geometry>
        <mesh
          filename="package://HotDog/meshes/RF_SHANK_LINK.STL" />
      </geometry>
      <material
        name="">
        <color
          rgba="0.752941176470588 0.752941176470588 0.752941176470588 1" />
      </material>
    </visual>
    <collision>
      <origin
        xyz="0 0 0"
        rpy="0 0 0" />
      <geometry>
        <mesh
          filename="package://HotDog/meshes/RF_SHANK_LINK.STL" />
      </geometry>
    </collision>
  </link>
  <joint
    name="RF_SHANK_JOINT"
    type="revolute">
    <origin
      xyz="0.13483 0.0019208 0"
      rpy="0 0 -1.5703" />
    <parent
      link="RF_THIGH_LINK" />
    <child
      link="RF_SHANK_LINK" />
    <axis
      xyz="0 0 -1" />
    <limit
      lower="-1.5708"
      upper="1.5708"
      effort="0"
      velocity="0" />
  </joint>
  <link
    name="RF_R_LINK">
    <inertial>
      <origin
        xyz="-2.77555756156289E-17 2.77555756156289E-17 -2.77555756156289E-17"
        rpy="0 0 0" />
      <mass
        value="6.54498469497874E-05" />
      <inertia
        ixx="1.63624617374468E-10"
        ixy="0"
        ixz="0"
        iyy="1.63624617374468E-10"
        iyz="0"
        izz="1.63624617374468E-10" />
    </inertial>
    <visual>
      <origin
        xyz="0 0 0"
        rpy="0 0 0" />
      <geometry>
        <mesh
          filename="package://HotDog/meshes/RF_R_LINK.STL" />
      </geometry>
      <material
        name="">
        <color
          rgba="0.792156862745098 0.819607843137255 0.933333333333333 1" />
      </material>
    </visual>
    <collision>
      <origin
        xyz="0 0 0"
        rpy="0 0 0" />
      <geometry>
        <mesh
          filename="package://HotDog/meshes/RF_R_LINK.STL" />
      </geometry>
    </collision>
  </link>
  <joint
    name="RF_R_JOINT"
    type="revolute">
    <origin
      xyz="0.122 0 0"
      rpy="1.5708 0 0" />
    <parent
      link="RF_SHANK_LINK" />
    <child
      link="RF_R_LINK" />
    <axis
      xyz="0 0 -1" />
    <limit
      lower="-1.5708"
      upper="1.5708"
      effort="0"
      velocity="0" />
  </joint>
  <link
    name="RF_P_LINK">
    <inertial>
      <origin
        xyz="0 1.38777878078145E-17 0"
        rpy="0 0 0" />
      <mass
        value="6.54498469497874E-05" />
      <inertia
        ixx="1.63624617374468E-10"
        ixy="0"
        ixz="0"
        iyy="1.63624617374468E-10"
        iyz="0"
        izz="1.63624617374468E-10" />
    </inertial>
    <visual>
      <origin
        xyz="0 0 0"
        rpy="0 0 0" />
      <geometry>
        <mesh
          filename="package://HotDog/meshes/RF_P_LINK.STL" />
      </geometry>
      <material
        name="">
        <color
          rgba="0.792156862745098 0.819607843137255 0.933333333333333 1" />
      </material>
    </visual>
    <collision>
      <origin
        xyz="0 0 0"
        rpy="0 0 0" />
      <geometry>
        <mesh
          filename="package://HotDog/meshes/RF_P_LINK.STL" />
      </geometry>
    </collision>
  </link>
  <joint
    name="RF_P_JOINT"
    type="revolute">
    <origin
      xyz="0 0 0"
      rpy="0 1.5708 0" />
    <parent
      link="RF_R_LINK" />
    <child
      link="RF_P_LINK" />
    <axis
      xyz="0 0 -1" />
    <limit
      lower="-1.5708"
      upper="1.5708"
      effort="0"
      velocity="0" />
  </joint>
  <link
    name="RF_Y_LINK">
    <inertial>
      <origin
        xyz="0 0 -1.38777878078145E-17"
        rpy="0 0 0" />
      <mass
        value="6.54498469497874E-05" />
      <inertia
        ixx="1.63624617374468E-10"
        ixy="0"
        ixz="0"
        iyy="1.63624617374468E-10"
        iyz="0"
        izz="1.63624617374468E-10" />
    </inertial>
    <visual>
      <origin
        xyz="0 0 0"
        rpy="0 0 0" />
      <geometry>
        <mesh
          filename="package://HotDog/meshes/RF_Y_LINK.STL" />
      </geometry>
      <material
        name="">
        <color
          rgba="0.792156862745098 0.819607843137255 0.933333333333333 1" />
      </material>
    </visual>
    <collision>
      <origin
        xyz="0 0 0"
        rpy="0 0 0" />
      <geometry>
        <mesh
          filename="package://HotDog/meshes/RF_Y_LINK.STL" />
      </geometry>
    </collision>
  </link>
  <joint
    name="RF_Y_JOINT"
    type="revolute">
    <origin
      xyz="0 0 0"
      rpy="1.5708 0 0" />
    <parent
      link="RF_P_LINK" />
    <child
      link="RF_Y_LINK" />
    <axis
      xyz="0 0 1" />
    <limit
      lower="-1.5708"
      upper="1.5708"
      effort="0"
      velocity="0" />
  </joint>
  <link
    name="RB_JIAN_LINK">
    <inertial>
      <origin
        xyz="-0.00133971122808706 4.14695766518826E-06 -0.0282268203441403"
        rpy="0 0 0" />
      <mass
        value="0.258003610332943" />
      <inertia
        ixx="0.000416230636705904"
        ixy="2.04095244653148E-08"
        ixz="-1.96174992192531E-07"
        iyy="0.000402490330372077"
        iyz="6.41537642602843E-09"
        izz="0.000140421858800084" />
    </inertial>
    <visual>
      <origin
        xyz="0 0 0"
        rpy="0 0 0" />
      <geometry>
        <mesh
          filename="package://HotDog/meshes/RB_JIAN_LINK.STL" />
      </geometry>
      <material
        name="">
        <color
          rgba="0.752941176470588 0.752941176470588 0.752941176470588 1" />
      </material>
    </visual>
    <collision>
      <origin
        xyz="0 0 0"
        rpy="0 0 0" />
      <geometry>
        <mesh
          filename="package://HotDog/meshes/RB_JIAN_LINK.STL" />
      </geometry>
    </collision>
  </link>
  <joint
    name="RB_JIAN_JOINT"
    type="revolute">
    <origin
      xyz="-0.1219 -0.04795 -0.001"
      rpy="1.5708 0 -1.5708" />
    <parent
      link="BODY_LINK" />
    <child
      link="RB_JIAN_LINK" />
    <axis
      xyz="0 0 1" />
    <limit
      lower="-1.5708"
      upper="1.5708"
      effort="0"
      velocity="0" />
  </joint>
  <link
    name="RB_THIGH_LINK">
    <inertial>
      <origin
        xyz="0.0513762577245795 0.000585803387600503 0.000195169976736645"
        rpy="0 0 0" />
      <mass
        value="0.0976231637562046" />
      <inertia
        ixx="1.83752301290234E-05"
        ixy="-1.86836389688719E-06"
        ixz="3.3227345653552E-07"
        iyy="0.000188585179296743"
        iyz="-7.56402083215947E-08"
        izz="0.000205508953934319" />
    </inertial>
    <visual>
      <origin
        xyz="0 0 0"
        rpy="0 0 0" />
      <geometry>
        <mesh
          filename="package://HotDog/meshes/RB_THIGH_LINK.STL" />
      </geometry>
      <material
        name="">
        <color
          rgba="0.752941176470588 0.752941176470588 0.752941176470588 1" />
      </material>
    </visual>
    <collision>
      <origin
        xyz="0 0 0"
        rpy="0 0 0" />
      <geometry>
        <mesh
          filename="package://HotDog/meshes/RB_THIGH_LINK.STL" />
      </geometry>
    </collision>
  </link>
  <joint
    name="RB_THIGH_JOINT"
    type="revolute">
    <origin
      xyz="0.05305 0 0"
      rpy="1.5708 -0.0032563 -1.5708" />
    <parent
      link="RB_JIAN_LINK" />
    <child
      link="RB_THIGH_LINK" />
    <axis
      xyz="0 0 -1" />
    <limit
      lower="-1.5708"
      upper="1.5708"
      effort="0"
      velocity="0" />
  </joint>
  <link
    name="RB_SHANK_LINK">
    <inertial>
      <origin
        xyz="0.0524784105682791 -0.00218665110929128 4.13396498318008E-06"
        rpy="0 0 0" />
      <mass
        value="0.0485390193489655" />
      <inertia
        ixx="7.20372534770678E-06"
        ixy="1.23442157049636E-06"
        ixz="1.93314144553433E-08"
        iyy="9.53226506117469E-05"
        iyz="7.45840146871638E-10"
        izz="9.98870131478521E-05" />
    </inertial>
    <visual>
      <origin
        xyz="0 0 0"
        rpy="0 0 0" />
      <geometry>
        <mesh
          filename="package://HotDog/meshes/RB_SHANK_LINK.STL" />
      </geometry>
      <material
        name="">
        <color
          rgba="0.752941176470588 0.752941176470588 0.752941176470588 1" />
      </material>
    </visual>
    <collision>
      <origin
        xyz="0 0 0"
        rpy="0 0 0" />
      <geometry>
        <mesh
          filename="package://HotDog/meshes/RB_SHANK_LINK.STL" />
      </geometry>
    </collision>
  </link>
  <joint
    name="RB_SHANK_JOINT"
    type="revolute">
    <origin
      xyz="0.13499 0.0014101 0"
      rpy="0 0 -1.5708" />
    <parent
      link="RB_THIGH_LINK" />
    <child
      link="RB_SHANK_LINK" />
    <axis
      xyz="0 0 -1" />
    <limit
      lower="-1.5708"
      upper="1.5708"
      effort="0"
      velocity="0" />
  </joint>
  <link
    name="RB_R_LINK">
    <inertial>
      <origin
        xyz="3.90312782094782E-18 0 -2.77555756156289E-17"
        rpy="0 0 0" />
      <mass
        value="6.54498469497874E-05" />
      <inertia
        ixx="1.63624617374468E-10"
        ixy="0"
        ixz="0"
        iyy="1.63624617374468E-10"
        iyz="0"
        izz="1.63624617374468E-10" />
    </inertial>
    <visual>
      <origin
        xyz="0 0 0"
        rpy="0 0 0" />
      <geometry>
        <mesh
          filename="package://HotDog/meshes/RB_R_LINK.STL" />
      </geometry>
      <material
        name="">
        <color
          rgba="0.792156862745098 0.819607843137255 0.933333333333333 1" />
      </material>
    </visual>
    <collision>
      <origin
        xyz="0 0 0"
        rpy="0 0 0" />
      <geometry>
        <mesh
          filename="package://HotDog/meshes/RB_R_LINK.STL" />
      </geometry>
    </collision>
  </link>
  <joint
    name="RB_R_JOINT"
    type="revolute">
    <origin
      xyz="0.122 -0.00039727 0"
      rpy="1.5708 0 -0.0032563" />
    <parent
      link="RB_SHANK_LINK" />
    <child
      link="RB_R_LINK" />
    <axis
      xyz="0 0 -1" />
    <limit
      lower="-1.5708"
      upper="1.5708"
      effort="0"
      velocity="0" />
  </joint>
  <link
    name="RB_P_LINK">
    <inertial>
      <origin
        xyz="2.77555756156289E-17 0 3.90312782094782E-18"
        rpy="0 0 0" />
      <mass
        value="6.54498469497874E-05" />
      <inertia
        ixx="1.63624617374468E-10"
        ixy="0"
        ixz="0"
        iyy="1.63624617374468E-10"
        iyz="0"
        izz="1.63624617374468E-10" />
    </inertial>
    <visual>
      <origin
        xyz="0 0 0"
        rpy="0 0 0" />
      <geometry>
        <mesh
          filename="package://HotDog/meshes/RB_P_LINK.STL" />
      </geometry>
      <material
        name="">
        <color
          rgba="0.792156862745098 0.819607843137255 0.933333333333333 1" />
      </material>
    </visual>
    <collision>
      <origin
        xyz="0 0 0"
        rpy="0 0 0" />
      <geometry>
        <mesh
          filename="package://HotDog/meshes/RB_P_LINK.STL" />
      </geometry>
    </collision>
  </link>
  <joint
    name="RB_P_JOINT"
    type="revolute">
    <origin
      xyz="0 0 0"
      rpy="0 1.5708 0" />
    <parent
      link="RB_R_LINK" />
    <child
      link="RB_P_LINK" />
    <axis
      xyz="0 0 -1" />
    <limit
      lower="-1.5708"
      upper="1.5708"
      effort="0"
      velocity="0" />
  </joint>
  <link
    name="RB_Y_LINK">
    <inertial>
      <origin
        xyz="2.77555756156289E-17 3.90312782094782E-18 0"
        rpy="0 0 0" />
      <mass
        value="6.54498469497874E-05" />
      <inertia
        ixx="1.63624617374468E-10"
        ixy="0"
        ixz="0"
        iyy="1.63624617374468E-10"
        iyz="0"
        izz="1.63624617374468E-10" />
    </inertial>
    <visual>
      <origin
        xyz="0 0 0"
        rpy="0 0 0" />
      <geometry>
        <mesh
          filename="package://HotDog/meshes/RB_Y_LINK.STL" />
      </geometry>
      <material
        name="">
        <color
          rgba="0.792156862745098 0.819607843137255 0.933333333333333 1" />
      </material>
    </visual>
    <collision>
      <origin
        xyz="0 0 0"
        rpy="0 0 0" />
      <geometry>
        <mesh
          filename="package://HotDog/meshes/RB_Y_LINK.STL" />
      </geometry>
    </collision>
  </link>
  <joint
    name="RB_Y_JOINT"
    type="revolute">
    <origin
      xyz="0 0 0"
      rpy="1.5708 0 0" />
    <parent
      link="RB_P_LINK" />
    <child
      link="RB_Y_LINK" />
    <axis
      xyz="0 0 1" />
    <limit
      lower="-1.5708"
      upper="1.5708"
      effort="0"
      velocity="0" />
  </joint>
</robot>